Workbook

Sheet RAW DATA
A1: Case_ID | B1: Date | C1: Agent_ID | D1: Agent_Name | E1: Team | F1: Channel_Type | G1: Contact_Type | H1: Issue_Category | I1: Handle_Time_Min | J1: Wait_Time_Min | K1: FCR_Flag | L1: CSAT_Score | M1: Sentiment | N1: Escalated | O1: Transfers | P1: Case_Outcome | Q1: Notes | R1: Month
A2: CC-10001 | C2: AG002 | D2: BOB NSHIMIYIMANA | E2: Inbound | F2: Team Alpha | G2: Chat | H2: Billing | J2: 4.3 | K2: Yes | M2: Positive | N2: No | O2: 0 | P2: Abandoned | Q2: Case handled by AG002 | S2: =IFERROR(L2,L3) -> 0
A3: CC-10002 | B3: 2024-02-17 | C3: AG004 | D3: David Habimana | E3: Outbound | F3: Team Beta | G3: Chat | H3: Returns | I3: 8.4 | J3: 6.7 | K3: Yes | L3: 4 | M3: Positive | N3: No | O3: 1 | P3: Escalated | Q3: Case handled by AG004 | S3: =IFERROR(L3,L4) -> 4
A4: CC-10003 | B4: 2024-03-22 | C4: AG007 | D4: Grace Uwase | E4: Email | F4: Team Gamma | G4: Phone | H4: Payment | I4: 7.1 | J4: 5 | K4: Yes | L4: 5 | M4: Positive | N4: No | O4: 1 | P4: Resolved | Q4: Case handled by AG007 | S4: =IFERROR(L4,L5) -> 5
A5: CC-10004 | B5: 2024-07-02 | C5: AG006 | D5: Frank Nzeyimana | E5: Email | F5: Team Gamma | G5: Phone | H5: Returns | I5: 3.7 | J5: 1.8 | K5: Yes | L5: 5 | M5: Very Negative | N5: No | O5: 0 | P5: Transferred | Q5: Case handled by AG006 | S5: =IFERROR(L5,L6) -> 5
A6: CC-10005 | B6: 2024-07-04 | C6: AG010 | D6: John Gasana | E6: Email | F6: Team Gamma | G6: Phone | H6: Technical | I6: 8.4 | J6: 4.7 | K6: Yes | L6: 5 | M6: Very Positive | N6: No | O6: 1 | P6: Resolved | Q6: Case handled by AG010 | S6: =IFERROR(L6,L7) -> 5
A7: CC-10006 | B7: 2024-05-22 | C7: AG008 | D7: Henry Bizimana | E7: Outbound | F7: Team Beta | G7: Phone | H7: Account | I7: 6.1 | J7: 2.6 | K7: Yes | L7: 4 | M7: Very Negative | N7: No | O7: 0 | P7: Callback | Q7: Case handled by AG008 | S7: =IFERROR(L7,L8) -> 4
A8: CC-10007 | B8: 2024-05-05 | C8: AG003 | D8: Claire Mukamana | E8: Outbound | F8: Team Beta | G8: Phone | H8: Shipping | I8: 5.7 | J8: 4.4 | K8: Yes | L8: 5 | M8: Positive | N8: No | O8: 0 | P8: Callback | Q8: Case handled by AG003 | S8: =IFERROR(L8,L9) -> 5
A9: CC-10008 | B9: 2024-06-10 | C9: AG007 | D9: Grace Uwase | E9: Email | F9: Team Gamma | G9: Chat | H9: Payment | I9: 7.8 | J9: 5.4 | K9: Yes | L9: 5 | M9: Very Positive | N9: No | O9: 1 | P9: Escalated | Q9: Case handled by AG007 | S9: =IFERROR(L9,L10) -> 5
A10: CC-10009 | B10: 2024-03-14 | C10: AG005 | D10: Eve Ingabire | E10: Inbound | F10: Team Alpha | G10: Chat | H10: General Inquiry | I10: 11.2 | J10: 6.5 | K10: Yes | L10: 4 | M10: Neutral | N10: No | O10: 1 | P10: Abandoned | Q10: Case handled by AG005 | S10: =IFERROR(L10,L11) -> 4
A11: CC-10010 | B11: 2024-03-11 | C11: AG009 | D11: Irene Mutesi | E11: Inbound | F11: Team Alpha | G11: Chat | H11: Technical | I11: 3 | J11: 4.1 | K11: Yes | L11: 5 | M11: Very Positive | N11: No | O11: 0 | P11: Escalated | Q11: Case handled by AG009 | S11: =IFERROR(L11,L12) -> 5
A12: CC-10011 | B12: 2024-07-14 | C12: AG010 | D12: John Gasana | E12: Email | F12: Team Gamma | G12: Email | H12: Returns | I12: 11.7 | J12: 3.9 | K12: Yes | L12: 5 | M12: Negative | N12: No | O12: 0 | P12: Resolved | Q12: Case handled by AG010 | S12: =IFERROR(L12,L13) -> 5
A13: CC-10012 | B13: 2024-02-27 | C13: AG005 | D13: Eve Ingabire | E13: Inbound | F13: Team Alpha | G13: Phone | H13: Technical | I13: 5 | J13: 4.9 | K13: Yes | L13: 5 | M13: Negative | N13: No | O13: 1 | P13: Abandoned | Q13: Case handled by AG005 | S13: =IFERROR(L13,L14) -> 5
A14: CC-10013 | B14: 2024-11-23 | C14: AG009 | D14: Irene Mutesi | E14: Inbound | F14: Team Alpha | G14: Phone | H14: Password Reset | I14: 6.7 | J14: 3.3 | K14: Yes | L14: 5 | M14: Positive | N14: No | O14: 0 | P14: Abandoned | Q14: Case handled by AG009 | S14: =IFERROR(L14,L15) -> 5
... A36: CC-10035 | B36: 2024-01-13 | C36: AG003 | D36: Claire Mukamana | E36: Outbound | F36: Team Beta | G36: Phone | H36: Technical | I36: 7.8 | J36: 2.2 | K36: Yes | L36: 5 | M36: Very Positive | N36: No | O36: 0 | P36: Callback | Q36: Case handled by AG003 | S36: =IFERROR(L36,L37) -> 5
A37: CC-10036 | B37: 2024-01-20 | C37: AG008 | D37: Henry Bizimana | E37: Outbound | F37: Team Beta | G37: Phone | H37: Billing | J37: 7.6 | K37: Yes | L37: 4 | M37: Neutral | N37: No | O37: 1 | P37: Escalated | Q37: Case handled by AG008 | S37: =IFERROR(L37,L38) -> 4
A38: CC-10037 | B38: 2024-07-23 | C38: AG006 | D38: Frank Nzeyimana | E38: Email | F38: Team Gamma | G38: Chat | H38: General Inquiry | I38: 7.8 | J38: 4.7 | K38: Yes | L38: 5 | M38: Positive | N38: No | O38: 1 | P38: Abandoned | Q38: Case handled by AG006 | S38: =IFERROR(L38,L39) -> 5
A39: CC-10038 | B39: 2024-02-29 | C39: AG005 | D39: Eve Ingabire | E39: Inbound | F39: Team Alpha | G39: Phone | H39: Payment | I39: 11.3 | J39: 8.6 | K39: Yes | L39: 3 | M39: Very Negative | N39: No | O39: 1 | P39: Callback | Q39: Case handled by AG005 | S39: =IFERROR(L39,L40) -> 3
A40: CC-10039 | B40: 2024-09-18 | C40: AG002 | D40: Bob Nshimiyimana | E40: Inbound | F40: Team Alpha | G40: Chat | H40: Technical | I40: 5 | J40: 5.7 | K40: No | L40: 3 | M40: Negative | N40: Yes | O40: 1 | P40: Callback | Q40: Case handled by AG002 | S40: =IFERROR(L40,L41) -> 3
A41: CC-10040 | B41: 2024-11-15 | C41: AG006 | D41: Frank Nzeyimana | E41: Email | F41: Team Gamma | G41: Phone | H41: Payment | I41: 7.2 | J41: 3.1 | K41: Yes | L41: 5 | M41: Negative | N41: No | O41: 1 | P41: Transferred | Q41: Case handled by AG006 | S41: =IFERROR(L41,L42) -> 5
A42: CC-10041 | B42: 2024-10-10 | C42: AG003 | D42: Claire Mukamana | E42: Outbound | F42: Team Beta | G42: Email | H42: Returns | I42: 9.6 | J42: 6.8 | K42: Yes | M42: Very Positive | N42: No | O42: 0 | P42: Abandoned | Q42: Case handled by AG003 | S42: =IFERROR(L42,L43) -> 0
A43: CC-10042 | B43: 2024-10-07 | C43: AG001 | D43: Alice Uwimana | E43: Inbound | F43: Team Alpha | G43: Chat | H43: Password Reset | I43: 7.3 | J43: 5.3 | K43: Yes | L43: 5 | M43: Neutral | N43: No | O43: 1 | P43: Transferred | Q43: Case handled by AG001 | S43: =IFERROR(L43,L44) -> 5
A44: CC-10043 | B44: 2024-09-18 | C44: AG008 | D44: Henry Bizimana | E44: Outbound | F44: Team Beta | G44: Email | H44: General Inquiry | I44: 10.1 | J44: 0 | K44: Yes | L44: 5 | M44: Positive | N44: No | O44: 0 | P44: Callback | Q44: Case handled by AG008 | S44: =IFERROR(L44,L45) -> 5
A45: CC-10044 | B45: 2024-04-30 | C45: AG005 | D45: Eve Ingabire | E45: Inbound | F45: Team Alpha | G45: Phone | H45: Password Reset | I45: 8.3 | J45: 5.3 | K45: No | L45: 1 | M45: Very Positive | N45: Yes | O45: 3 | P45: Abandoned | Q45: Case handled by AG005 | S45: =IFERROR(L45,L46) -> 1
A46: CC-10045 | B46: 2024-11-18 | C46: AG010 | D46: John Gasana | E46: Email | F46: Team Gamma | G46: Phone | H46: Technical | I46: 9.6 | J46: 6.9 | K46: Yes | L46: 4 | M46: Very Positive | N46: No | O46: 0 | P46: Escalated | Q46: Case handled by AG010 | S46: =IFERROR(L46,L47) -> 4
A47: CC-10046 | B47: 2024-04-22 | C47: AG003 | D47: Claire Mukamana | E47: Outbound | F47: Team Beta | G47: Chat | H47: Account | I47: 9.5 | J47: 1.1 | K47: Yes | L47: 4 | M47: Very Positive | N47: No | O47: 0 | P47: Resolved | Q47: Case handled by AG003 | S47: =IFERROR(L47,L48) -> 4
A48: CC-10047 | B48: 2024-12-07 | C48: AG009 | D48: Irene Mutesi | E48: Inbound | F48: Team Alpha | G48: Chat | H48: Account | I48: 12 | J48: 3.8 | K48: No | L48: 5 | M48: Very Positive | N48: No | O48: 1 | P48: Abandoned | Q48: Case handled by AG009 | S48: =IFERROR(L48,L49) -> 5
A49: CC-10048 | B49: 2024-08-18 | C49: AG005 | D49: Eve Ingabire | E49: Inbound | F49: Team Alpha | G49: Phone | H49: Returns | I49: 8.1 | J49: 0.2 | K49: No | L49: 3 | M49: Neutral | N49: No | O49: 1 | P49: Transferred | Q49: Case handled by AG005 | S49: =IFERROR(L49,L50) -> 3
A50: CC-10049 | B50: 2024-05-19 | C50: AG006 | D50: Frank Nzeyimana | E50: Email | F50: Team Gamma | G50: Phone | H50: Technical | I50: 6.4 | J50: 6.3 | K50: Yes | L50: 3 | M50: Very Positive | N50: No | O50: 1 | P50: Escalated | Q50: Case handled by AG006 | S50: =IFERROR(L50,L51) -> 3
A51: CC-10050 | B51: 2024-07-27 | C51: AG006 | D51: Frank Nzeyimana | E51: Email | F51: Team Gamma | G51: Chat | H51: Password Reset | I51: 5 | J51: 3.5 | K51: No | L51: 3 | M51: Positive | N51: Yes | O51: 0 | P51: Abandoned | Q51: Case handled by AG006 | S51: =IFERROR(L51,L52) -> 3
A52: CC-10051 | C52: AG005 | D52: EVE INGABIRE | E52: Inbound | F52: Team Alpha | G52: Email | H52: Shipping | I52: 8.1 | J52: 0.1 | K52: Yes | L52: 5 | M52: Very Positive | N52: No | O52: 1 | P52: Abandoned | Q52: Case handled by AG005 | S52: =IFERROR(L52,L53) -> 5
A53: CC-10052 | B53: 2024-04-22 | C53: AG005 | D53: Eve Ingabire | E53: Inbound | F53: Team Alpha | G53: Chat | H53: Account | I53: 7.3 | J53: 4.2 | K53: Yes | L53: 4 | M53: Very Negative | N53: No | O53: 1 | P53: Escalated | Q53: Case handled by AG005 | S53: =IFERROR(L53,L54) -> 4
A54: CC-10053 | B54: 2024-09-30 | C54: AG001 | D54: Alice Uwimana | E54: Inbound | F54: Team Alpha | G54: Phone | H54: Password Reset | I54: 11.3 | J54: 2.5 | K54: Yes | L54: 5 | M54: Neutral | N54: No | O54: 0 | P54: Transferred | Q54: Case handled by AG001 | S54: =IFERROR(L54,L55) -> 5
A55: CC-10054 | B55: 2024-01-26 | C55: AG005 | D55: Eve Ingabire | E55: Inbound | F55: Team Alpha | G55: Chat | H55: Returns | I55: 6.5 | J55: 4.9 | K55: Yes | L55: 4 | M55: Positive | N55: No | O55: 1 | P55: Callback | Q55: Case handled by AG005 | S55: =IFERROR(L55,L56) -> 4
A56: CC-10055 | B56: 2024-08-28 | C56: AG001 | D56: Alice Uwimana | E56: Inbound | F56: Team Alpha | G56: Phone | H56: Billing | I56: 8 | J56: 3.3 | K56: Yes | L56: 5 | M56: Neutral | N56: No | O56: 0 | P56: Resolved | Q56: Case handled by AG001 | S56: =IFERROR(L56,L57) -> 5
A57: CC-10056 | B57: 2024-04-12 | C57: AG001 | D57: Alice Uwimana | E57: Inbound | F57: Team Alpha | G57: Phone | H57: Password Reset | I57: 6.4 | J57: 3 | K57: Yes | L57: 4 | M57: Negative | N57: No | O57: 0 | P57: Abandoned | Q57: Case handled by AG001 | S57: =IFERROR(L57,L58) -> 4
A58: CC-10057 | B58: 2024-07-07 | C58: AG003 | D58: Claire Mukamana | E58: Outbound | F58: Team Beta | G58: Phone | H58: Billing | I58: 1.9 | J58: 0.8 | K58: Yes | L58: 5 | M58: Negative | N58: No | O58: 0 | P58: Callback | Q58: Case handled by AG003 | S58: =IFERROR(L58,L59) -> 5
A59: CC-10058 | B59: 2024-10-21 | C59: AG007 | D59: Grace Uwase | E59: Email | F59: Team Gamma | G59: Phone | H59: Technical | I59: 4.2 | J59: 5.9 | K59: No | L59: 2 | M59: Very Negative | N59: No | O59: 0 | P59: Resolved | Q59: Case handled by AG007 | S59: =IFERROR(L59,L60) -> 2
A60: CC-10059 | B60: 2024-01-22 | C60: AG006 | D60: Frank Nzeyimana | E60: Email | F60: Team Gamma | G60: Chat | H60: Technical | I60: 3.7 | J60: 3.4 | K60: No | L60: 2 | M60: Very Positive | N60: No | O60: 0 | P60: Transferred | Q60: Case handled by AG006 | S60: =IFERROR(L60,L61) -> 2
A61: CC-10060 | B61: 2024-07-04 | C61: AG008 | D61: Henry Bizimana | E61: Outbound | F61: Team Beta | G61: Email | H61: Password Reset | I61: 7.1 | J61: 1.9 | K61: Yes | L61: 5 | M61: Very Positive | N61: No | O61: 1 | P61: Abandoned | Q61: Case handled by AG008 | S61: =IFERROR(L61,L62) -> 5
...

Sheet Cleaned Data 
A1: Case_ID | B1: Date | C1: Agent_ID | D1: Agent_Name | E1: Channel_Type | F1: Team | G1: Contact_Type | H1: Issue_Category | I1: Handle_Time_Min | J1: Wait_Time_Min | K1: FCR_Flag | L1: CSAT_Score | M1: Sentiment | N1: Escalated | O1: Transfers | P1: Case_Outcome | Q1: Notes | R1: Month | S1: Month Number | T1: Quarter | U1: HT | V1: Missing-Date | W1: Duplicates
A2: CC-10001 | B2: =IFERROR(IF('RAW DATA'!B2="","Missing",TEXT('RAW DATA'!B2,"YYYY-MM-DAY")),0) -> Missing | C2: AG002 | D2: =PROPER('RAW DATA'!D2) -> Bob Nshimiyimana | E2: Inbound | F2: Team Alpha | G2: Chat | H2: Billing | I2: =IFERROR(IF('RAW DATA'!I2="",AVERAGE('RAW DATA'!I$2:I$301),'RAW DATA'!I2),0) -> 7.6041237 | J2: 4.3 | K2: Yes | L2: =IFERROR(IF('RAW DATA'!L2="",3,'RAW DATA'!L2),3) -> 3 | M2: Positive | N2: No | O2: 0 | P2: Abandoned | Q2: Case handled by AG002 | R2: =IFERROR(TEXT('RAW DATA'!B2,"MMMM"),"UKNNOWN") -> January | S2: =IFERROR(MONTH('RAW DATA'!B2),0) -> 1 | T2: =IF(S2<=3,"Q1",IF(S2<=6,"Q2",IF(S2<=9,"Q3","Q4"))) -> Q1 | U2: =IF('RAW DATA'!I2>20,"High",IF('RAW DATA'!I2>10,"Medium","Low")) -> Low | V2: =IF('RAW DATA'!B2="","Yes","No") -> Yes | W2: =IF(COUNTIF(A$2:A301,A2)>1,"Duplicate","OK") -> OK | X2: =IFERROR(L2,L3) -> 3
A3: CC-10002 | B3: =IFERROR(IF('RAW DATA'!B3="","Missing",TEXT('RAW DATA'!B3,"YYYY-MM-DAY")),0) -> 2024-02-17A24 | C3: AG004 | D3: =PROPER('RAW DATA'!D3) -> David Habimana | E3: Outbound | F3: Team Beta | G3: Chat | H3: Returns | I3: =IFERROR(IF('RAW DATA'!I3="",AVERAGE('RAW DATA'!I$2:I$301),'RAW DATA'!I3),0) -> 8.4 | J3: 6.7 | K3: Yes | L3: =IFERROR(IF('RAW DATA'!L3="",3,'RAW DATA'!L3),3) -> 4 | M3: Positive | N3: No | O3: 1 | P3: Escalated | Q3: Case handled by AG004 | R3: =IFERROR(TEXT('RAW DATA'!B3,"MMMM"),"UKNNOWN") -> February | S3: =IFERROR(MONTH('RAW DATA'!B3),0) -> 2 | T3: =IF(S3<=3,"Q1",IF(S3<=6,"Q2",IF(S3<=9,"Q3","Q4"))) -> Q1 | U3: =IF('RAW DATA'!I3>20,"High",IF('RAW DATA'!I3>10,"Medium","Low")) -> Low | V3: =IF('RAW DATA'!B3="","Yes","No") -> No | W3: =IF(COUNTIF(A$2:A302,A3)>1,"Duplicate","OK") -> OK | X3: =IFERROR(L3,L4) -> 4
A4: CC-10003 | B4: =IFERROR(IF('RAW DATA'!B4="","Missing",TEXT('RAW DATA'!B4,"YYYY-MM-DAY")),"INVALID DATE") -> 2024-03-22A24 | C4: AG007 | D4: =PROPER('RAW DATA'!D4) -> Grace Uwase | E4: Email | F4: Team Gamma | G4: Phone | H4: Payment | I4: =IFERROR(IF('RAW DATA'!I4="",AVERAGE('RAW DATA'!I$2:I$301),'RAW DATA'!I4),0) -> 7.1 | J4: 5 | K4: Yes | L4: =IFERROR(IF('RAW DATA'!L4="",3,'RAW DATA'!L4),3) -> 5 | M4: Positive | N4: No | O4: 1 | P4: Resolved | Q4: Case handled by AG007 | R4: =IFERROR(TEXT('RAW DATA'!B4,"MMMM"),"UKNNOWN") -> March | S4: =IFERROR(MONTH('RAW DATA'!B4),0) -> 3 | T4: =IF(S4<=3,"Q1",IF(S4<=6,"Q2",IF(S4<=9,"Q3","Q4"))) -> Q1 | U4: =IF('RAW DATA'!I4>20,"High",IF('RAW DATA'!I4>10,"Medium","Low")) -> Low | V4: =IF('RAW DATA'!B4="","Yes","No") -> No | W4: =IF(COUNTIF(A$2:A303,A4)>1,"Duplicate","OK") -> OK | X4: =IFERROR(L4,L5) -> 5
A5: CC-10004 | B5: =IFERROR(IF('RAW DATA'!B5="","Missing",TEXT('RAW DATA'!B5,"YYYY-MM-DAY")),"INVALID DATE") -> 2024-07-2A24 | C5: AG006 | D5: =PROPER('RAW DATA'!D5) -> Frank Nzeyimana | E5: Email | F5: Team Gamma | G5: Phone | H5: Returns | I5: =IFERROR(IF('RAW DATA'!I5="",AVERAGE('RAW DATA'!I$2:I$301),'RAW DATA'!I5),0) -> 3.7 | J5: 1.8 | K5: Yes | L5: =IFERROR(IF('RAW DATA'!L5="",3,'RAW DATA'!L5),3) -> 5 | M5: Very Negative | N5: No | O5: 0 | P5: Transferred | Q5: Case handled by AG006 | R5: =IFERROR(TEXT('RAW DATA'!B5,"MMMM"),"UKNNOWN") -> July | S5: =IFERROR(MONTH('RAW DATA'!B5),0) -> 7 | T5: =IF(S5<=3,"Q1",IF(S5<=6,"Q2",IF(S5<=9,"Q3","Q4"))) -> Q3 | U5: =IF('RAW DATA'!I5>20,"High",IF('RAW DATA'!I5>10,"Medium","Low")) -> Low | V5: =IF('RAW DATA'!B5="","Yes","No") -> No | W5: =IF(COUNTIF(A$2:A304,A5)>1,"Duplicate","OK") -> OK | X5: =IFERROR(L5,L6) -> 5
A6: CC-10005 | B6: =IFERROR(IF('RAW DATA'!B6="","Missing",TEXT('RAW DATA'!B6,"YYYY-MM-DAY")),"INVALID DATE") -> 2024-07-4A24 | C6: AG010 | D6: =PROPER('RAW DATA'!D6) -> John Gasana | E6: Email | F6: Team Gamma | G6: Phone | H6: Technical | I6: =IFERROR(IF('RAW DATA'!I6="",AVERAGE('RAW DATA'!I$2:I$301),'RAW DATA'!I6),0) -> 8.4 | J6: 4.7 | K6: Yes | L6: =IFERROR(IF('RAW DATA'!L6="",3,'RAW DATA'!L6),3) -> 5 | M6: Very Positive | N6: No | O6: 1 | P6: Resolved | Q6: Case handled by AG010 | R6: =IFERROR(TEXT('RAW DATA'!B6,"MMMM"),"UKNNOWN") -> July | S6: =IFERROR(MONTH('RAW DATA'!B6),0) -> 7 | T6: =IF(S6<=3,"Q1",IF(S6<=6,"Q2",IF(S6<=9,"Q3","Q4"))) -> Q3 | U6: =IF('RAW DATA'!I6>20,"High",IF('RAW DATA'!I6>10,"Medium","Low")) -> Low | V6: =IF('RAW DATA'!B6="","Yes","No") -> No | W6: =IF(COUNTIF(A$2:A305,A6)>1,"Duplicate","OK") -> OK | X6: =IFERROR(L6,L7) -> 5
A7: CC-10006 | B7: =IFERROR(IF('RAW DATA'!B7="","Missing",TEXT('RAW DATA'!B7,"YYYY-MM-DAY")),"INVALID DATE") -> 2024-05-22A24 | C7: AG008 | D7: =PROPER('RAW DATA'!D7) -> Henry Bizimana | E7: Outbound | F7: Team Beta | G7: Phone | H7: Account | I7: =IFERROR(IF('RAW DATA'!I7="",AVERAGE('RAW DATA'!I$2:I$301),'RAW DATA'!I7),0) -> 6.1 | J7: 2.6 | K7: Yes | L7: =IFERROR(IF('RAW DATA'!L7="",3,'RAW DATA'!L7),3) -> 4 | M7: Very Negative | N7: No | O7: 0 | P7: Callback | Q7: Case handled by AG008 | R7: =IFERROR(TEXT('RAW DATA'!B7,"MMMM"),"UKNNOWN") -> May | S7: =IFERROR(MONTH('RAW DATA'!B7),0) -> 5 | T7: =IF(S7<=3,"Q1",IF(S7<=6,"Q2",IF(S7<=9,"Q3","Q4"))) -> Q2 | U7: =IF('RAW DATA'!I7>20,"High",IF('RAW DATA'!I7>10,"Medium","Low")) -> Low | V7: =IF('RAW DATA'!B7="","Yes","No") -> No | W7: =IF(COUNTIF(A$2:A306,A7)>1,"Duplicate","OK") -> OK | X7: =IFERROR(L7,L8) -> 4
A8: CC-10007 | B8: =IFERROR(IF('RAW DATA'!B8="","Missing",TEXT('RAW DATA'!B8,"YYYY-MM-DAY")),"INVALID DATE") -> 2024-05-5A24 | C8: AG003 | D8: =PROPER('RAW DATA'!D8) -> Claire Mukamana | E8: Outbound | F8: Team Beta | G8: Phone | H8: Shipping | I8: =IFERROR(IF('RAW DATA'!I8="",AVERAGE('RAW DATA'!I$2:I$301),'RAW DATA'!I8),0) -> 5.7 | J8: 4.4 | K8: Yes | L8: =IFERROR(IF('RAW DATA'!L8="",3,'RAW DATA'!L8),3) -> 5 | M8: Positive | N8: No | O8: 0 | P8: Callback | Q8: Case handled by AG003 | R8: =IFERROR(TEXT('RAW DATA'!B8,"MMMM"),"UKNNOWN") -> May | S8: =IFERROR(MONTH('RAW DATA'!B8),0) -> 5 | T8: =IF(S8<=3,"Q1",IF(S8<=6,"Q2",IF(S8<=9,"Q3","Q4"))) -> Q2 | U8: =IF('RAW DATA'!I8>20,"High",IF('RAW DATA'!I8>10,"Medium","Low")) -> Low | V8: =IF('RAW DATA'!B8="","Yes","No") -> No | W8: =IF(COUNTIF(A$2:A307,A8)>1,"Duplicate","OK") -> OK | X8: =IFERROR(L8,L9) -> 5
A9: CC-10008 | B9: =IFERROR(IF('RAW DATA'!B9="","Missing",TEXT('RAW DATA'!B9,"YYYY-MM-DAY")),"INVALID DATE") -> 2024-06-10A24 | C9: AG007 | D9: =PROPER('RAW DATA'!D9) -> Grace Uwase | E9: Email | F9: Team Gamma | G9: Chat | H9: Payment | I9: =IFERROR(IF('RAW DATA'!I9="",AVERAGE('RAW DATA'!I$2:I$301),'RAW DATA'!I9),0) -> 7.8 | J9: 5.4 | K9: Yes | L9: =IFERROR(IF('RAW DATA'!L9="",3,'RAW DATA'!L9),3) -> 5 | M9: Very Positive | N9: No | O9: 1 | P9: Escalated | Q9: Case handled by AG007 | R9: =IFERROR(TEXT('RAW DATA'!B9,"MMMM"),"UKNNOWN") -> June | S9: =IFERROR(MONTH('RAW DATA'!B9),0) -> 6 | T9: =IF(S9<=3,"Q1",IF(S9<=6,"Q2",IF(S9<=9,"Q3","Q4"))) -> Q2 | U9: =IF('RAW DATA'!I9>20,"High",IF('RAW DATA'!I9>10,"Medium","Low")) -> Low | V9: =IF('RAW DATA'!B9="","Yes","No") -> No | W9: =IF(COUNTIF(A$2:A308,A9)>1,"Duplicate","OK") -> OK | X9: =IFERROR(L9,L10) -> 5
A10: CC-10009 | B10: =IFERROR(IF('RAW DATA'!B10="","Missing",TEXT('RAW DATA'!B10,"YYYY-MM-DAY")),"INVALID DATE") -> 2024-03-14A24 | C10: AG005 | D10: =PROPER('RAW DATA'!D10) -> Eve Ingabire | E10: Inbound | F10: Team Alpha | G10: Chat | H10: General Inquiry | I10: =IFERROR(IF('RAW DATA'!I10="",AVERAGE('RAW DATA'!I$2:I$301),'RAW DATA'!I10),0) -> 11.2 | J10: 6.5 | K10: Yes | L10: =IFERROR(IF('RAW DATA'!L10="",3,'RAW DATA'!L10),3) -> 4 | M10: Neutral | N10: No | O10: 1 | P10: Abandoned | Q10: Case handled by AG005 | R10: =IFERROR(TEXT('RAW DATA'!B10,"MMMM"),"UKNNOWN") -> March | S10: =IFERROR(MONTH('RAW DATA'!B10),0) -> 3 | T10: =IF(S10<=3,"Q1",IF(S10<=6,"Q2",IF(S10<=9,"Q3","Q4"))) -> Q1 | U10: =IF('RAW DATA'!I10>20,"High",IF('RAW DATA'!I10>10,"Medium","Low")) -> Medium | V10: =IF('RAW DATA'!B10="","Yes","No") -> No | W10: =IF(COUNTIF(A$2:A309,A10)>1,"Duplicate","OK") -> OK | X10: =IFERROR(L10,L11) -> 4
A11: CC-10010 | B11: =IFERROR(IF('RAW DATA'!B11="","Missing",TEXT('RAW DATA'!B11,"YYYY-MM-DAY")),"INVALID DATE") -> 2024-03-11A24 | C11: AG009 | D11: =PROPER('RAW DATA'!D11) -> Irene Mutesi | E11: Inbound | F11: Team Alpha | G11: Chat | H11: Technical | I11: =IFERROR(IF('RAW DATA'!I11="",AVERAGE('RAW DATA'!I$2:I$301),'RAW DATA'!I11),0) -> 3 | J11: 4.1 | K11: Yes | L11: =IFERROR(IF('RAW DATA'!L11="",3,'RAW DATA'!L11),3) -> 5 | M11: Very Positive | N11: No | O11: 0 | P11: Escalated | Q11: Case handled by AG009 | R11: =IFERROR(TEXT('RAW DATA'!B11,"MMMM"),"UKNNOWN") -> March | S11: =IFERROR(MONTH('RAW DATA'!B11),0) -> 3 | T11: =IF(S11<=3,"Q1",IF(S11<=6,"Q2",IF(S11<=9,"Q3","Q4"))) -> Q1 | U11: =IF('RAW DATA'!I11>20,"High",IF('RAW DATA'!I11>10,"Medium","Low")) -> Low | V11: =IF('RAW DATA'!B11="","Yes","No") -> No | W11: =IF(COUNTIF(A$2:A310,A11)>1,"Duplicate","OK") -> OK | X11: =IFERROR(L11,L12) -> 5
A12: CC-10011 | B12: =IFERROR(IF('RAW DATA'!B12="","Missing",TEXT('RAW DATA'!B12,"YYYY-MM-DAY")),"INVALID DATE") -> 2024-07-14A24 | C12: AG010 | D12: =PROPER('RAW DATA'!D12) -> John Gasana | E12: Email | F12: Team Gamma | G12: Email | H12: Returns | I12: =IFERROR(IF('RAW DATA'!I12="",AVERAGE('RAW DATA'!I$2:I$301),'RAW DATA'!I12),0) -> 11.7 | J12: 3.9 | K12: Yes | L12: =IFERROR(IF('RAW DATA'!L12="",3,'RAW DATA'!L12),3) -> 5 | M12: Negative | N12: No | O12: 0 | P12: Resolved | Q12: Case handled by AG010 | R12: =IFERROR(TEXT('RAW DATA'!B12,"MMMM"),"UKNNOWN") -> July | S12: =IFERROR(MONTH('RAW DATA'!B12),0) -> 7 | T12: =IF(S12<=3,"Q1",IF(S12<=6,"Q2",IF(S12<=9,"Q3","Q4"))) -> Q3 | U12: =IF('RAW DATA'!I12>20,"High",IF('RAW DATA'!I12>10,"Medium","Low")) -> Medium | V12: =IF('RAW DATA'!B12="","Yes","No") -> No | W12: =IF(COUNTIF(A$2:A311,A12)>1,"Duplicate","OK") -> OK | X12: =IFERROR(L12,L13) -> 5
A13: CC-10012 | B13: =IFERROR(IF('RAW DATA'!B13="","Missing",TEXT('RAW DATA'!B13,"YYYY-MM-DAY")),"INVALID DATE") -> 2024-02-27A24 | C13: AG005 | D13: =PROPER('RAW DATA'!D13) -> Eve Ingabire | E13: Inbound | F13: Team Alpha | G13: Phone | H13: Technical | I13: =IFERROR(IF('RAW DATA'!I13="",AVERAGE('RAW DATA'!I$2:I$301),'RAW DATA'!I13),0) -> 5 | J13: 4.9 | K13: Yes | L13: =IFERROR(IF('RAW DATA'!L13="",3,'RAW DATA'!L13),3) -> 5 | M13: Negative | N13: No | O13: 1 | P13: Abandoned | Q13: Case handled by AG005 | R13: =IFERROR(TEXT('RAW DATA'!B13,"MMMM"),"UKNNOWN") -> February | S13: =IFERROR(MONTH('RAW DATA'!B13),0) -> 2 | T13: =IF(S13<=3,"Q1",IF(S13<=6,"Q2",IF(S13<=9,"Q3","Q4"))) -> Q1 | U13: =IF('RAW DATA'!I13>20,"High",IF('RAW DATA'!I13>10,"Medium","Low")) -> Low | V13: =IF('RAW DATA'!B13="","Yes","No") -> No | W13: =IF(COUNTIF(A$2:A312,A13)>1,"Duplicate","OK") -> OK | X13: =IFERROR(L13,L14) -> 5
A14: CC-10013 | B14: =IFERROR(IF('RAW DATA'!B14="","Missing",TEXT('RAW DATA'!B14,"YYYY-MM-DAY")),"INVALID DATE") -> 2024-11-23A24 | C14: AG009 | D14: =PROPER('RAW DATA'!D14) -> Irene Mutesi | E14: Inbound | F14: Team Alpha | G14: Phone | H14: Password Reset | I14: =IFERROR(IF('RAW DATA'!I14="",AVERAGE('RAW DATA'!I$2:I$301),'RAW DATA'!I14),0) -> 6.7 | J14: 3.3 | K14: Yes | L14: =IFERROR(IF('RAW DATA'!L14="",3,'RAW DATA'!L14),3) -> 5 | M14: Positive | N14: No | O14: 0 | P14: Abandoned | Q14: Case handled by AG009 | R14: =IFERROR(TEXT('RAW DATA'!B14,"MMMM"),"UKNNOWN") -> November | S14: =IFERROR(MONTH('RAW DATA'!B14),0) -> 11 | T14: =IF(S14<=3,"Q1",IF(S14<=6,"Q2",IF(S14<=9,"Q3","Q4"))) -> Q4 | U14: =IF('RAW DATA'!I14>20,"High",IF('RAW DATA'!I14>10,"Medium","Low")) -> Low | V14: =IF('RAW DATA'!B14="","Yes","No") -> No | W14: =IF(COUNTIF(A$2:A313,A14)>1,"Duplicate","OK") -> OK | X14: =IFERROR(L14,L15) -> 5
A15: CC-10014 | B15: =IFERROR(IF('RAW DATA'!B15="","Missing",TEXT('RAW DATA'!B15,"YYYY-MM-DAY")),"INVALID DATE") -> 2024-02-27A24 | C15: AG006 | D15: =PROPER('RAW DATA'!D15) -> Frank Nzeyimana | E15: Email | F15: Team Gamma | G15: Phone | H15: Technical | I15: =IFERROR(IF('RAW DATA'!I15="",AVERAGE('RAW DATA'!I$2:I$301),'RAW DATA'!I15),0) -> 12.1 | J15: 1.4 | K15: Yes | L15: =IFERROR(IF('RAW DATA'!L15="",3,'RAW DATA'!L15),3) -> 4 | M15: Very Positive | N15: No | O15: 0 | P15: Abandoned | Q15: Case handled by AG006 | R15: =IFERROR(TEXT('RAW DATA'!B15,"MMMM"),"UKNNOWN") -> February | S15: =IFERROR(MONTH('RAW DATA'!B15),0) -> 2 | T15: =IF(S15<=3,"Q1",IF(S15<=6,"Q2",IF(S15<=9,"Q3","Q4"))) -> Q1 | U15: =IF('RAW DATA'!I15>20,"High",IF('RAW DATA'!I15>10,"Medium","Low")) -> Medium | V15: =IF('RAW DATA'!B15="","Yes","No") -> No | W15: =IF(COUNTIF(A$2:A314,A15)>1,"Duplicate","OK") -> OK | X15: =IFERROR(L15,L16) -> 4
... A51: CC-10050 | B51: =IFERROR(IF('RAW DATA'!B51="","Missing",TEXT('RAW DATA'!B51,"YYYY-MM-DAY")),"INVALID DATE") -> 2024-07-27A24 | C51: AG006 | D51: =PROPER('RAW DATA'!D51) -> Frank Nzeyimana | E51: Email | F51: Team Gamma | G51: Chat | H51: Password Reset | I51: =IFERROR(IF('RAW DATA'!I51="",AVERAGE('RAW DATA'!I$2:I$301),'RAW DATA'!I51),0) -> 5 | J51: 3.5 | K51: No | L51: =IFERROR(IF('RAW DATA'!L51="",3,'RAW DATA'!L51),3) -> 3 | M51: Positive | N51: Yes | O51: 0 | P51: Abandoned | Q51: Case handled by AG006 | R51: =IFERROR(TEXT('RAW DATA'!B51,"MMMM"),"UKNNOWN") -> July | S51: =IFERROR(MONTH('RAW DATA'!B51),0) -> 7 | T51: =IF(S51<=3,"Q1",IF(S51<=6,"Q2",IF(S51<=9,"Q3","Q4"))) -> Q3 | U51: =IF('RAW DATA'!I51>20,"High",IF('RAW DATA'!I51>10,"Medium","Low")) -> Low | V51: =IF('RAW DATA'!B51="","Yes","No") -> No | W51: =IF(COUNTIF(A$2:A350,A51)>1,"Duplicate","OK") -> OK | X51: =IFERROR(L51,L52) -> 3
A52: CC-10051 | C52: AG005 | D52: =PROPER('RAW DATA'!D52) -> Eve Ingabire | E52: Inbound | F52: Team Alpha | G52: Email | H52: Shipping | I52: =IFERROR(IF('RAW DATA'!I52="",AVERAGE('RAW DATA'!I$2:I$301),'RAW DATA'!I52),0) -> 8.1 | J52: 0.1 | K52: Yes | L52: =IFERROR(IF('RAW DATA'!L52="",3,'RAW DATA'!L52),3) -> 5 | M52: Very Positive | N52: No | O52: 1 | P52: Abandoned | Q52: Case handled by AG005 | R52: =IFERROR(TEXT('RAW DATA'!B52,"MMMM"),"UKNNOWN") -> January | S52: =IFERROR(MONTH('RAW DATA'!B52),0) -> 1 | T52: =IF(S52<=3,"Q1",IF(S52<=6,"Q2",IF(S52<=9,"Q3","Q4"))) -> Q1 | U52: =IF('RAW DATA'!I52>20,"High",IF('RAW DATA'!I52>10,"Medium","Low")) -> Low | V52: =IF('RAW DATA'!B52="","Yes","No") -> Yes | W52: =IF(COUNTIF(A$2:A351,A52)>1,"Duplicate","OK") -> OK | X52: =IFERROR(L52,L53) -> 5
A53: CC-10052 | B53: 2024-04-22 | C53: AG005 | D53: =PROPER('RAW DATA'!D53) -> Eve Ingabire | E53: Inbound | F53: Team Alpha | G53: Chat | H53: Account | I53: =IFERROR(IF('RAW DATA'!I53="",AVERAGE('RAW DATA'!I$2:I$301),'RAW DATA'!I53),0) -> 7.3 | J53: 4.2 | K53: Yes | L53: =IFERROR(IF('RAW DATA'!L53="",3,'RAW DATA'!L53),3) -> 4 | M53: Very Negative | N53: No | O53: 1 | P53: Escalated | Q53: Case handled by AG005 | R53: =IFERROR(TEXT('RAW DATA'!B53,"MMMM"),"UKNNOWN") -> April | S53: =IFERROR(MONTH('RAW DATA'!B53),0) -> 4 | T53: =IF(S53<=3,"Q1",IF(S53<=6,"Q2",IF(S53<=9,"Q3","Q4"))) -> Q2 | U53: =IF('RAW DATA'!I53>20,"High",IF('RAW DATA'!I53>10,"Medium","Low")) -> Low | V53: =IF('RAW DATA'!B53="","Yes","No") -> No | W53: =IF(COUNTIF(A$2:A352,A53)>1,"Duplicate","OK") -> OK | X53: =IFERROR(L53,L54) -> 4
A54: CC-10053 | B54: 2024-09-30 | C54: AG001 | D54: =PROPER('RAW DATA'!D54) -> Alice Uwimana | E54: Inbound | F54: Team Alpha | G54: Phone | H54: Password Reset | I54: =IFERROR(IF('RAW DATA'!I54="",AVERAGE('RAW DATA'!I$2:I$301),'RAW DATA'!I54),0) -> 11.3 | J54: 2.5 | K54: Yes | L54: =IFERROR(IF('RAW DATA'!L54="",3,'RAW DATA'!L54),3) -> 5 | M54: Neutral | N54: No | O54: 0 | P54: Transferred | Q54: Case handled by AG001 | R54: =IFERROR(TEXT('RAW DATA'!B54,"MMMM"),"UKNNOWN") -> September | S54: =IFERROR(MONTH('RAW DATA'!B54),0) -> 9 | T54: =IF(S54<=3,"Q1",IF(S54<=6,"Q2",IF(S54<=9,"Q3","Q4"))) -> Q3 | U54: =IF('RAW DATA'!I54>20,"High",IF('RAW DATA'!I54>10,"Medium","Low")) -> Medium | V54: =IF('RAW DATA'!B54="","Yes","No") -> No | W54: =IF(COUNTIF(A$2:A353,A54)>1,"Duplicate","OK") -> OK | X54: =IFERROR(L54,L55) -> 5
A55: CC-10054 | B55: 2024-01-26 | C55: AG005 | D55: =PROPER('RAW DATA'!D55) -> Eve Ingabire | E55: Inbound | F55: Team Alpha | G55: Chat | H55: Returns | I55: =IFERROR(IF('RAW DATA'!I55="",AVERAGE('RAW DATA'!I$2:I$301),'RAW DATA'!I55),0) -> 6.5 | J55: 4.9 | K55: Yes | L55: =IFERROR(IF('RAW DATA'!L55="",3,'RAW DATA'!L55),3) -> 4 | M55: Positive | N55: No | O55: 1 | P55: Callback | Q55: Case handled by AG005 | R55: =IFERROR(TEXT('RAW DATA'!B55,"MMMM"),"UKNNOWN") -> January | S55: =IFERROR(MONTH('RAW DATA'!B55),0) -> 1 | T55: =IF(S55<=3,"Q1",IF(S55<=6,"Q2",IF(S55<=9,"Q3","Q4"))) -> Q1 | U55: =IF('RAW DATA'!I55>20,"High",IF('RAW DATA'!I55>10,"Medium","Low")) -> Low | V55: =IF('RAW DATA'!B55="","Yes","No") -> No | W55: =IF(COUNTIF(A$2:A354,A55)>1,"Duplicate","OK") -> OK | X55: =IFERROR(L55,L56) -> 4
A56: CC-10055 | B56: 2024-08-28 | C56: AG001 | D56: =PROPER('RAW DATA'!D56) -> Alice Uwimana | E56: Inbound | F56: Team Alpha | G56: Phone | H56: Billing | I56: =IFERROR(IF('RAW DATA'!I56="",AVERAGE('RAW DATA'!I$2:I$301),'RAW DATA'!I56),0) -> 8 | J56: 3.3 | K56: Yes | L56: =IFERROR(IF('RAW DATA'!L56="",3,'RAW DATA'!L56),3) -> 5 | M56: Neutral | N56: No | O56: 0 | P56: Resolved | Q56: Case handled by AG001 | R56: =IFERROR(TEXT('RAW DATA'!B56,"MMMM"),"UKNNOWN") -> August | S56: =IFERROR(MONTH('RAW DATA'!B56),0) -> 8 | T56: =IF(S56<=3,"Q1",IF(S56<=6,"Q2",IF(S56<=9,"Q3","Q4"))) -> Q3 | U56: =IF('RAW DATA'!I56>20,"High",IF('RAW DATA'!I56>10,"Medium","Low")) -> Low | V56: =IF('RAW DATA'!B56="","Yes","No") -> No | W56: =IF(COUNTIF(A$2:A355,A56)>1,"Duplicate","OK") -> OK | X56: =IFERROR(L56,L57) -> 5
A57: CC-10056 | B57: 2024-04-12 | C57: AG001 | D57: =PROPER('RAW DATA'!D57) -> Alice Uwimana | E57: Inbound | F57: Team Alpha | G57: Phone | H57: Password Reset | I57: =IFERROR(IF('RAW DATA'!I57="",AVERAGE('RAW DATA'!I$2:I$301),'RAW DATA'!I57),0) -> 6.4 | J57: 3 | K57: Yes | L57: =IFERROR(IF('RAW DATA'!L57="",3,'RAW DATA'!L57),3) -> 4 | M57: Negative | N57: No | O57: 0 | P57: Abandoned | Q57: Case handled by AG001 | R57: =IFERROR(TEXT('RAW DATA'!B57,"MMMM"),"UKNNOWN") -> April | S57: =IFERROR(MONTH('RAW DATA'!B57),0) -> 4 | T57: =IF(S57<=3,"Q1",IF(S57<=6,"Q2",IF(S57<=9,"Q3","Q4"))) -> Q2 | U57: =IF('RAW DATA'!I57>20,"High",IF('RAW DATA'!I57>10,"Medium","Low")) -> Low | V57: =IF('RAW DATA'!B57="","Yes","No") -> No | W57: =IF(COUNTIF(A$2:A356,A57)>1,"Duplicate","OK") -> OK | X57: =IFERROR(L57,L58) -> 4
A58: CC-10057 | B58: 2024-07-07 | C58: AG003 | D58: =PROPER('RAW DATA'!D58) -> Claire Mukamana | E58: Outbound | F58: Team Beta | G58: Phone | H58: Billing | I58: =IFERROR(IF('RAW DATA'!I58="",AVERAGE('RAW DATA'!I$2:I$301),'RAW DATA'!I58),0) -> 1.9 | J58: 0.8 | K58: Yes | L58: =IFERROR(IF('RAW DATA'!L58="",3,'RAW DATA'!L58),3) -> 5 | M58: Negative | N58: No | O58: 0 | P58: Callback | Q58: Case handled by AG003 | R58: =IFERROR(TEXT('RAW DATA'!B58,"MMMM"),"UKNNOWN") -> July | S58: =IFERROR(MONTH('RAW DATA'!B58),0) -> 7 | T58: =IF(S58<=3,"Q1",IF(S58<=6,"Q2",IF(S58<=9,"Q3","Q4"))) -> Q3 | U58: =IF('RAW DATA'!I58>20,"High",IF('RAW DATA'!I58>10,"Medium","Low")) -> Low | V58: =IF('RAW DATA'!B58="","Yes","No") -> No | W58: =IF(COUNTIF(A$2:A357,A58)>1,"Duplicate","OK") -> OK | X58: =IFERROR(L58,L59) -> 5
A59: CC-10058 | B59: 2024-10-21 | C59: AG007 | D59: =PROPER('RAW DATA'!D59) -> Grace Uwase | E59: Email | F59: Team Gamma | G59: Phone | H59: Technical | I59: =IFERROR(IF('RAW DATA'!I59="",AVERAGE('RAW DATA'!I$2:I$301),'RAW DATA'!I59),0) -> 4.2 | J59: 5.9 | K59: No | L59: =IFERROR(IF('RAW DATA'!L59="",3,'RAW DATA'!L59),3) -> 2 | M59: Very Negative | N59: No | O59: 0 | P59: Resolved | Q59: Case handled by AG007 | R59: =IFERROR(TEXT('RAW DATA'!B59,"MMMM"),"UKNNOWN") -> October | S59: =IFERROR(MONTH('RAW DATA'!B59),0) -> 10 | T59: =IF(S59<=3,"Q1",IF(S59<=6,"Q2",IF(S59<=9,"Q3","Q4"))) -> Q4 | U59: =IF('RAW DATA'!I59>20,"High",IF('RAW DATA'!I59>10,"Medium","Low")) -> Low | V59: =IF('RAW DATA'!B59="","Yes","No") -> No | W59: =IF(COUNTIF(A$2:A358,A59)>1,"Duplicate","OK") -> OK | X59: =IFERROR(L59,L60) -> 2
A60: CC-10059 | B60: 2024-01-22 | C60: AG006 | D60: =PROPER('RAW DATA'!D60) -> Frank Nzeyimana | E60: Email | F60: Team Gamma | G60: Chat | H60: Technical | I60: =IFERROR(IF('RAW DATA'!I60="",AVERAGE('RAW DATA'!I$2:I$301),'RAW DATA'!I60),0) -> 3.7 | J60: 3.4 | K60: No | L60: =IFERROR(IF('RAW DATA'!L60="",3,'RAW DATA'!L60),3) -> 2 | M60: Very Positive | N60: No | O60: 0 | P60: Transferred | Q60: Case handled by AG006 | R60: =IFERROR(TEXT('RAW DATA'!B60,"MMMM"),"UKNNOWN") -> January | S60: =IFERROR(MONTH('RAW DATA'!B60),0) -> 1 | T60: =IF(S60<=3,"Q1",IF(S60<=6,"Q2",IF(S60<=9,"Q3","Q4"))) -> Q1 | U60: =IF('RAW DATA'!I60>20,"High",IF('RAW DATA'!I60>10,"Medium","Low")) -> Low | V60: =IF('RAW DATA'!B60="","Yes","No") -> No | W60: =IF(COUNTIF(A$2:A359,A60)>1,"Duplicate","OK") -> OK | X60: =IFERROR(L60,L61) -> 2
A61: CC-10060 | B61: 2024-07-04 | C61: AG008 | D61: =PROPER('RAW DATA'!D61) -> Henry Bizimana | E61: Outbound | F61: Team Beta | G61: Email | H61: Password Reset | I61: =IFERROR(IF('RAW DATA'!I61="",AVERAGE('RAW DATA'!I$2:I$301),'RAW DATA'!I61),0) -> 7.1 | J61: 1.9 | K61: Yes | L61: =IFERROR(IF('RAW DATA'!L61="",3,'RAW DATA'!L61),3) -> 5 | M61: Very Positive | N61: No | O61: 1 | P61: Abandoned | Q61: Case handled by AG008 | R61: =IFERROR(TEXT('RAW DATA'!B61,"MMMM"),"UKNNOWN") -> July | S61: =IFERROR(MONTH('RAW DATA'!B61),0) -> 7 | T61: =IF(S61<=3,"Q1",IF(S61<=6,"Q2",IF(S61<=9,"Q3","Q4"))) -> Q3 | U61: =IF('RAW DATA'!I61>20,"High",IF('RAW DATA'!I61>10,"Medium","Low")) -> Low | V61: =IF('RAW DATA'!B61="","Yes","No") -> No | W61: =IF(COUNTIF(A$2:A360,A61)>1,"Duplicate","OK") -> OK | X61: =IFERROR(L61,L62) -> 5
A62: CC-10061 | B62: 2024-08-11 | C62: AG010 | D62: =PROPER('RAW DATA'!D62) -> John Gasana | E62: Email | F62: Team Gamma | G62: Chat | H62: Shipping | I62: =IFERROR(IF('RAW DATA'!I62="",AVERAGE('RAW DATA'!I$2:I$301),'RAW DATA'!I62),0) -> 7.3 | J62: 7.9 | K62: Yes | L62: =IFERROR(IF('RAW DATA'!L62="",3,'RAW DATA'!L62),3) -> 5 | M62: Very Positive | N62: No | O62: 0 | P62: Callback | Q62: Case handled by AG010 | R62: =IFERROR(TEXT('RAW DATA'!B62,"MMMM"),"UKNNOWN") -> August | S62: =IFERROR(MONTH('RAW DATA'!B62),0) -> 8 | T62: =IF(S62<=3,"Q1",IF(S62<=6,"Q2",IF(S62<=9,"Q3","Q4"))) -> Q3 | U62: =IF('RAW DATA'!I62>20,"High",IF('RAW DATA'!I62>10,"Medium","Low")) -> Low | V62: =IF('RAW DATA'!B62="","Yes","No") -> No | W62: =IF(COUNTIF(A$2:A361,A62)>1,"Duplicate","OK") -> OK | X62: =IFERROR(L62,L63) -> 5
A63: CC-10062 | B63: 2024-10-18 | C63: AG010 | D63: =PROPER('RAW DATA'!D63) -> John Gasana | E63: Email | F63: Team Gamma | G63: Chat | H63: Shipping | I63: =IFERROR(IF('RAW DATA'!I63="",AVERAGE('RAW DATA'!I$2:I$301),'RAW DATA'!I63),0) -> 6.7 | J63: 2.4 | K63: Yes | L63: =IFERROR(IF('RAW DATA'!L63="",3,'RAW DATA'!L63),3) -> 4 | M63: Negative | N63: No | O63: 1 | P63: Escalated | Q63: Case handled by AG010 | R63: =IFERROR(TEXT('RAW DATA'!B63,"MMMM"),"UKNNOWN") -> October | S63: =IFERROR(MONTH('RAW DATA'!B63),0) -> 10 | T63: =IF(S63<=3,"Q1",IF(S63<=6,"Q2",IF(S63<=9,"Q3","Q4"))) -> Q4 | U63: =IF('RAW DATA'!I63>20,"High",IF('RAW DATA'!I63>10,"Medium","Low")) -> Low | V63: =IF('RAW DATA'!B63="","Yes","No") -> No | W63: =IF(COUNTIF(A$2:A362,A63)>1,"Duplicate","OK") -> OK | X63: =IFERROR(L63,L64) -> 4
A64: CC-10063 | B64: 2024-05-12 | C64: AG006 | D64: =PROPER('RAW DATA'!D64) -> Frank Nzeyimana | E64: Email | F64: Team Gamma | G64: Phone | H64: Technical | I64: =IFERROR(IF('RAW DATA'!I64="",AVERAGE('RAW DATA'!I$2:I$301),'RAW DATA'!I64),0) -> 7.3 | J64: 6.6 | K64: Yes | L64: =IFERROR(IF('RAW DATA'!L64="",3,'RAW DATA'!L64),3) -> 5 | M64: Neutral | N64: No | O64: 0 | P64: Abandoned | Q64: Case handled by AG006 | R64: =IFERROR(TEXT('RAW DATA'!B64,"MMMM"),"UKNNOWN") -> May | S64: =IFERROR(MONTH('RAW DATA'!B64),0) -> 5 | T64: =IF(S64<=3,"Q1",IF(S64<=6,"Q2",IF(S64<=9,"Q3","Q4"))) -> Q2 | U64: =IF('RAW DATA'!I64>20,"High",IF('RAW DATA'!I64>10,"Medium","Low")) -> Low | V64: =IF('RAW DATA'!B64="","Yes","No") -> No | W64: =IF(COUNTIF(A$2:A363,A64)>1,"Duplicate","OK") -> OK | X64: =IFERROR(L64,L65) -> 5
... A101: CC-10100 | B101: 2024-02-16 | C101: AG005 | D101: =PROPER('RAW DATA'!D101) -> Eve Ingabire | E101: Inbound | F101: Team Alpha | G101: Phone | H101: Password Reset | I101: =IFERROR(IF('RAW DATA'!I101="",AVERAGE('RAW DATA'!I$2:I$301),'RAW DATA'!I101),0) -> 6.6 | J101: 5.8 | K101: No | L101: =IFERROR(IF('RAW DATA'!L101="",3,'RAW DATA'!L101),3) -> 3 | M101: Negative | N101: No | O101: 1 | P101: Escalated | Q101: Case handled by AG005 | R101: =IFERROR(TEXT('RAW DATA'!B101,"MMMM"),"UKNNOWN") -> February | S101: =IFERROR(MONTH('RAW DATA'!B101),0) -> 2 | T101: =IF(S101<=3,"Q1",IF(S101<=6,"Q2",IF(S101<=9,"Q3","Q4"))) -> Q1 | U101: =IF('RAW DATA'!I101>20,"High",IF('RAW DATA'!I101>10,"Medium","Low")) -> Low | V101: =IF('RAW DATA'!B101="","Yes","No") -> No | W101: =IF(COUNTIF(A$2:A400,A101)>1,"Duplicate","OK") -> OK | X101: =IFERROR(L101,L102) -> 3
A102: CC-10101 | C102: AG002 | D102: =PROPER('RAW DATA'!D102) -> Bob Nshimiyimana | E102: Inbound | F102: Team Alpha | G102: Email | H102: General Inquiry | I102: =IFERROR(IF('RAW DATA'!I102="",AVERAGE('RAW DATA'!I$2:I$301),'RAW DATA'!I102),0) -> 6.8 | J102: 4.2 | K102: Yes | L102: =IFERROR(IF('RAW DATA'!L102="",3,'RAW DATA'!L102),3) -> 5 | M102: Positive | N102: No | O102: 0 | P102: Transferred | Q102: Case handled by AG002 | R102: =IFERROR(TEXT('RAW DATA'!B102,"MMMM"),"UKNNOWN") -> January | S102: =IFERROR(MONTH('RAW DATA'!B102),0) -> 1 | T102: =IF(S102<=3,"Q1",IF(S102<=6,"Q2",IF(S102<=9,"Q3","Q4"))) -> Q1 | U102: =IF('RAW DATA'!I102>20,"High",IF('RAW DATA'!I102>10,"Medium","Low")) -> Low | V102: =IF('RAW DATA'!B102="","Yes","No") -> Yes | W102: =IF(COUNTIF(A$2:A401,A102)>1,"Duplicate","OK") -> OK | X102: =IFERROR(L102,L103) -> 5
A103: CC-10102 | B103: 2024-07-21 | C103: AG001 | D103: =PROPER('RAW DATA'!D103) -> Alice Uwimana | E103: Inbound | F103: Team Alpha | G103: Chat | H103: General Inquiry | I103: =IFERROR(IF('RAW DATA'!I103="",AVERAGE('RAW DATA'!I$2:I$301),'RAW DATA'!I103),0) -> 7.9 | J103: 5 | K103: Yes | L103: =IFERROR(IF('RAW DATA'!L103="",3,'RAW DATA'!L103),3) -> 4 | M103: Positive | N103: No | O103: 1 | P103: Abandoned | Q103: Case handled by AG001 | R103: =IFERROR(TEXT('RAW DATA'!B103,"MMMM"),"UKNNOWN") -> July | S103: =IFERROR(MONTH('RAW DATA'!B103),0) -> 7 | T103: =IF(S103<=3,"Q1",IF(S103<=6,"Q2",IF(S103<=9,"Q3","Q4"))) -> Q3 | U103: =IF('RAW DATA'!I103>20,"High",IF('RAW DATA'!I103>10,"Medium","Low")) -> Low | V103: =IF('RAW DATA'!B103="","Yes","No") -> No | W103: =IF(COUNTIF(A$2:A402,A103)>1,"Duplicate","OK") -> OK | X103: =IFERROR(L103,L104) -> 4
A104: CC-10103 | B104: 2024-12-11 | C104: AG004 | D104: =PROPER('RAW DATA'!D104) -> David Habimana | E104: Outbound | F104: Team Beta | G104: Phone | H104: Technical | I104: =IFERROR(IF('RAW DATA'!I104="",AVERAGE('RAW DATA'!I$2:I$301),'RAW DATA'!I104),0) -> 3.9 | J104: 4.5 | K104: Yes | L104: =IFERROR(IF('RAW DATA'!L104="",3,'RAW DATA'!L104),3) -> 5 | M104: Very Positive | N104: No | O104: 1 | P104: Abandoned | Q104: Case handled by AG004 | R104: =IFERROR(TEXT('RAW DATA'!B104,"MMMM"),"UKNNOWN") -> December | S104: =IFERROR(MONTH('RAW DATA'!B104),0) -> 12 | T104: =IF(S104<=3,"Q1",IF(S104<=6,"Q2",IF(S104<=9,"Q3","Q4"))) -> Q4 | U104: =IF('RAW DATA'!I104>20,"High",IF('RAW DATA'!I104>10,"Medium","Low")) -> Low | V104: =IF('RAW DATA'!B104="","Yes","No") -> No | W104: =IF(COUNTIF(A$2:A403,A104)>1,"Duplicate","OK") -> OK | X104: =IFERROR(L104,L105) -> 5
A105: CC-10104 | B105: 2024-12-24 | C105: AG005 | D105: =PROPER('RAW DATA'!D105) -> Eve Ingabire | E105: Inbound | F105: Team Alpha | G105: Phone | H105: Shipping | I105: =IFERROR(IF('RAW DATA'!I105="",AVERAGE('RAW DATA'!I$2:I$301),'RAW DATA'!I105),0) -> 7.1 | J105: 3.2 | K105: No | L105: =IFERROR(IF('RAW DATA'!L105="",3,'RAW DATA'!L105),3) -> 1 | M105: Very Negative | N105: Yes | O105: 3 | P105: Resolved | Q105: Case handled by AG005 | R105: =IFERROR(TEXT('RAW DATA'!B105,"MMMM"),"UKNNOWN") -> December | S105: =IFERROR(MONTH('RAW DATA'!B105),0) -> 12 | T105: =IF(S105<=3,"Q1",IF(S105<=6,"Q2",IF(S105<=9,"Q3","Q4"))) -> Q4 | U105: =IF('RAW DATA'!I105>20,"High",IF('RAW DATA'!I105>10,"Medium","Low")) -> Low | V105: =IF('RAW DATA'!B105="","Yes","No") -> No | W105: =IF(COUNTIF(A$2:A404,A105)>1,"Duplicate","OK") -> OK | X105: =IFERROR(L105,L106) -> 1
A106: CC-10105 | B106: 2024-03-10 | C106: AG007 | D106: =PROPER('RAW DATA'!D106) -> Grace Uwase | E106: Email | F106: Team Gamma | G106: Phone | H106: Payment | I106: =IFERROR(IF('RAW DATA'!I106="",AVERAGE('RAW DATA'!I$2:I$301),'RAW DATA'!I106),0) -> 3.7 | J106: 4.9 | K106: Yes | L106: =IFERROR(IF('RAW DATA'!L106="",3,'RAW DATA'!L106),3) -> 5 | M106: Positive | N106: No | O106: 1 | P106: Abandoned | Q106: Case handled by AG007 | R106: =IFERROR(TEXT('RAW DATA'!B106,"MMMM"),"UKNNOWN") -> March | S106: =IFERROR(MONTH('RAW DATA'!B106),0) -> 3 | T106: =IF(S106<=3,"Q1",IF(S106<=6,"Q2",IF(S106<=9,"Q3","Q4"))) -> Q1 | U106: =IF('RAW DATA'!I106>20,"High",IF('RAW DATA'!I106>10,"Medium","Low")) -> Low | V106: =IF('RAW DATA'!B106="","Yes","No") -> No | W106: =IF(COUNTIF(A$2:A405,A106)>1,"Duplicate","OK") -> OK | X106: =IFERROR(L106,L107) -> 5
A107: CC-10106 | B107: 2024-09-07 | C107: AG010 | D107: =PROPER('RAW DATA'!D107) -> John Gasana | E107: Email | F107: Team Gamma | G107: Phone | H107: General Inquiry | I107: =IFERROR(IF('RAW DATA'!I107="",AVERAGE('RAW DATA'!I$2:I$301),'RAW DATA'!I107),0) -> 7.6041237 | J107: 6.7 | K107: No | L107: =IFERROR(IF('RAW DATA'!L107="",3,'RAW DATA'!L107),3) -> 1 | M107: Positive | N107: Yes | O107: 3 | P107: Transferred | Q107: Case handled by AG010 | R107: =IFERROR(TEXT('RAW DATA'!B107,"MMMM"),"UKNNOWN") -> September | S107: =IFERROR(MONTH('RAW DATA'!B107),0) -> 9 | T107: =IF(S107<=3,"Q1",IF(S107<=6,"Q2",IF(S107<=9,"Q3","Q4"))) -> Q3 | U107: =IF('RAW DATA'!I107>20,"High",IF('RAW DATA'!I107>10,"Medium","Low")) -> Low | V107: =IF('RAW DATA'!B107="","Yes","No") -> No | W107: =IF(COUNTIF(A$2:A406,A107)>1,"Duplicate","OK") -> OK | X107: =IFERROR(L107,L108) -> 1
A108: CC-10107 | B108: 2024-12-17 | C108: AG006 | D108: =PROPER('RAW DATA'!D108) -> Frank Nzeyimana | E108: Email | F108: Team Gamma | G108: Phone | H108: Technical | I108: =IFERROR(IF('RAW DATA'!I108="",AVERAGE('RAW DATA'!I$2:I$301),'RAW DATA'!I108),0) -> 1 | J108: 2.5 | K108: Yes | L108: =IFERROR(IF('RAW DATA'!L108="",3,'RAW DATA'!L108),3) -> 4 | M108: Very Positive | N108: No | O108: 1 | P108: Callback | Q108: Case handled by AG006 | R108: =IFERROR(TEXT('RAW DATA'!B108,"MMMM"),"UKNNOWN") -> December | S108: =IFERROR(MONTH('RAW DATA'!B108),0) -> 12 | T108: =IF(S108<=3,"Q1",IF(S108<=6,"Q2",IF(S108<=9,"Q3","Q4"))) -> Q4 | U108: =IF('RAW DATA'!I108>20,"High",IF('RAW DATA'!I108>10,"Medium","Low")) -> Low | V108: =IF('RAW DATA'!B108="","Yes","No") -> No | W108: =IF(COUNTIF(A$2:A407,A108)>1,"Duplicate","OK") -> OK | X108: =IFERROR(L108,L109) -> 4
A109: CC-10108 | B109: 2024-02-16 | C109: AG004 | D109: =PROPER('RAW DATA'!D109) -> David Habimana | E109: Outbound | F109: Team Beta | G109: Email | H109: Shipping | I109: =IFERROR(IF('RAW DATA'!I109="",AVERAGE('RAW DATA'!I$2:I$301),'RAW DATA'!I109),0) -> 5.5 | J109: 1.9 | K109: No | L109: =IFERROR(IF('RAW DATA'!L109="",3,'RAW DATA'!L109),3) -> 1 | M109: Positive | N109: No | O109: 0 | P109: Escalated | Q109: Case handled by AG004 | R109: =IFERROR(TEXT('RAW DATA'!B109,"MMMM"),"UKNNOWN") -> February | S109: =IFERROR(MONTH('RAW DATA'!B109),0) -> 2 | T109: =IF(S109<=3,"Q1",IF(S109<=6,"Q2",IF(S109<=9,"Q3","Q4"))) -> Q1 | U109: =IF('RAW DATA'!I109>20,"High",IF('RAW DATA'!I109>10,"Medium","Low")) -> Low | V109: =IF('RAW DATA'!B109="","Yes","No") -> No | W109: =IF(COUNTIF(A$2:A408,A109)>1,"Duplicate","OK") -> OK | X109: =IFERROR(L109,L110) -> 1
A110: CC-10109 | B110: 2024-10-10 | C110: AG004 | D110: =PROPER('RAW DATA'!D110) -> David Habimana | E110: Outbound | F110: Team Beta | G110: Phone | H110: Account | I110: =IFERROR(IF('RAW DATA'!I110="",AVERAGE('RAW DATA'!I$2:I$301),'RAW DATA'!I110),0) -> 3.3 | J110: 2.1 | K110: Yes | L110: =IFERROR(IF('RAW DATA'!L110="",3,'RAW DATA'!L110),3) -> 3 | M110: Very Negative | N110: No | O110: 0 | P110: Callback | Q110: Case handled by AG004 | R110: =IFERROR(TEXT('RAW DATA'!B110,"MMMM"),"UKNNOWN") -> October | S110: =IFERROR(MONTH('RAW DATA'!B110),0) -> 10 | T110: =IF(S110<=3,"Q1",IF(S110<=6,"Q2",IF(S110<=9,"Q3","Q4"))) -> Q4 | U110: =IF('RAW DATA'!I110>20,"High",IF('RAW DATA'!I110>10,"Medium","Low")) -> Low | V110: =IF('RAW DATA'!B110="","Yes","No") -> No | W110: =IF(COUNTIF(A$2:A409,A110)>1,"Duplicate","OK") -> OK | X110: =IFERROR(L110,L111) -> 3
A111: CC-10110 | B111: 2024-05-08 | C111: AG003 | D111: =PROPER('RAW DATA'!D111) -> Claire Mukamana | E111: Outbound | F111: Team Beta | G111: Phone | H111: Billing | I111: =IFERROR(IF('RAW DATA'!I111="",AVERAGE('RAW DATA'!I$2:I$301),'RAW DATA'!I111),0) -> 12.6 | J111: 6.6 | K111: No | L111: =IFERROR(IF('RAW DATA'!L111="",3,'RAW DATA'!L111),3) -> 3 | M111: Neutral | N111: No | O111: 0 | P111: Abandoned | Q111: Case handled by AG003 | R111: =IFERROR(TEXT('RAW DATA'!B111,"MMMM"),"UKNNOWN") -> May | S111: =IFERROR(MONTH('RAW DATA'!B111),0) -> 5 | T111: =IF(S111<=3,"Q1",IF(S111<=6,"Q2",IF(S111<=9,"Q3","Q4"))) -> Q2 | U111: =IF('RAW DATA'!I111>20,"High",IF('RAW DATA'!I111>10,"Medium","Low")) -> Medium | V111: =IF('RAW DATA'!B111="","Yes","No") -> No | W111: =IF(COUNTIF(A$2:A410,A111)>1,"Duplicate","OK") -> OK | X111: =IFERROR(L111,L112) -> 3
...

Sheet Analysis
A1: 📊 A. FCR Rate by Team (COUNTIFS)
A2: Team | B2: Total Cases | C2: FCR = Yes | D2: FCR = No | E2: FCR Rate %
A3: Team Alpha | B3: =COUNTIF('Cleaned Data '!F$2:F301,Analysis!A3) -> 119 | C3: =COUNTIFS('Cleaned Data '!F2:F301,Analysis!A3,'Cleaned Data '!K2:K301,"Yes") -> 86 | D3: =COUNTIFS('Cleaned Data '!F2:F301,Analysis!A3,'Cleaned Data '!K2:K301,"No") -> 33 | E3: =IFERROR(C3/B3,0) -> 0.72268908
A4: Team Beta | B4: =COUNTIF('Cleaned Data '!F$2:F302,Analysis!A4) -> 94 | C4: =COUNTIFS('Cleaned Data '!F3:F302,Analysis!A4,'Cleaned Data '!K3:K302,"Yes") -> 73 | D4: =COUNTIFS('Cleaned Data '!F3:F302,Analysis!A4,'Cleaned Data '!K3:K302,"No") -> 21 | E4: =IFERROR(C4/B4,0) -> 0.77659574
A5: Team Gamma | B5: =COUNTIF('Cleaned Data '!F$2:F303,Analysis!A5) -> 87 | C5: =COUNTIFS('Cleaned Data '!F4:F303,Analysis!A5,'Cleaned Data '!K4:K303,"Yes") -> 65 | D5: =COUNTIFS('Cleaned Data '!F4:F303,Analysis!A5,'Cleaned Data '!K4:K303,"No") -> 22 | E5: =IFERROR(C5/B5,0) -> 0.74712644
A8: 📊 B. Avg CSAT & Handle Time by Issue (AVERAGEIFS)
A9: Issue Category | B9: Avg CSAT | C9: Avg Handle Time | D9: Case Count
A10: Billing | B10: =IFERROR(AVERAGEIF('Cleaned Data '!H2:H301,Analysis!A10,'Cleaned Data '!L2:L301),0) -> 3.9428571 | C10: =IFERROR(AVERAGEIF('Cleaned Data '!H$2:H$301,Analysis!A10,'Cleaned Data '!I$2:I$301),0) -> 7.6204713 | D10: =COUNTIF('Cleaned Data '!H$2:H$4301,Analysis!A10) -> 35
A11: Technical | B11: =IFERROR(AVERAGEIF('Cleaned Data '!H3:H302,Analysis!A11,'Cleaned Data '!L3:L302),0) -> 3.8837209 | C11: =IFERROR(AVERAGEIF('Cleaned Data '!H$2:H$301,Analysis!A11,'Cleaned Data '!I$2:I$301),0) -> 7.2651163 | D11: =COUNTIF('Cleaned Data '!H$2:H$4301,Analysis!A11) -> 43
A12: Account | B12: =IFERROR(AVERAGEIF('Cleaned Data '!H4:H303,Analysis!A12,'Cleaned Data '!L4:L303),0) -> 4.0263158 | C12: =IFERROR(AVERAGEIF('Cleaned Data '!H$2:H$301,Analysis!A12,'Cleaned Data '!I$2:I$301),0) -> 7.5054802 | D12: =COUNTIF('Cleaned Data '!H$2:H$4301,Analysis!A12) -> 38
A13: Shipping | B13: =IFERROR(AVERAGEIF('Cleaned Data '!H5:H304,Analysis!A13,'Cleaned Data '!L5:L304),0) -> 3.6333333 | C13: =IFERROR(AVERAGEIF('Cleaned Data '!H$2:H$301,Analysis!A13,'Cleaned Data '!I$2:I$301),0) -> 7.6066667 | D13: =COUNTIF('Cleaned Data '!H$2:H$4301,Analysis!A13) -> 30
A14: Returns | B14: =IFERROR(AVERAGEIF('Cleaned Data '!H6:H305,Analysis!A14,'Cleaned Data '!L6:L305),0) -> 3.9615385 | C14: =IFERROR(AVERAGEIF('Cleaned Data '!H$2:H$301,Analysis!A14,'Cleaned Data '!I$2:I$301),0) -> 7.2107143 | D14: =COUNTIF('Cleaned Data '!H$2:H$4301,Analysis!A14) -> 28
A15: General Inquiry | B15: =IFERROR(AVERAGEIF('Cleaned Data '!H7:H306,Analysis!A15,'Cleaned Data '!L7:L306),0) -> 3.6956522 | C15: =IFERROR(AVERAGEIF('Cleaned Data '!H$2:H$301,Analysis!A15,'Cleaned Data '!I$2:I$301),0) -> 8.3566114 | D15: =COUNTIF('Cleaned Data '!H$2:H$4301,Analysis!A15) -> 46
A16: Payment | B16: =IFERROR(AVERAGEIF('Cleaned Data '!H8:H307,Analysis!A16,'Cleaned Data '!L8:L307),0) -> 3.8974359 | C16: =IFERROR(AVERAGEIF('Cleaned Data '!H$2:H$301,Analysis!A16,'Cleaned Data '!I$2:I$301),0) -> 7.7951031 | D16: =COUNTIF('Cleaned Data '!H$2:H$4301,Analysis!A16) -> 40
A17: Password Reset | B17: =IFERROR(AVERAGEIF('Cleaned Data '!H9:H308,Analysis!A17,'Cleaned Data '!L9:L308),0) -> 4.05 | C17: =IFERROR(AVERAGEIF('Cleaned Data '!H$2:H$301,Analysis!A17,'Cleaned Data '!I$2:I$301),0) -> 7.2651031 | D17: =COUNTIF('Cleaned Data '!H$2:H$4301,Analysis!A17) -> 40
A19: 📊 C. Monthly KPI Summary
A20: Month | B20: Cases | C20: FCR Yes | D20: FCR Rate | E20: Avg CSAT | F20: Avg Handle Time | G20: Escalations
A21: January | B21: =IFERROR(COUNTIF('Cleaned Data '!R2:R301,Analysis!A21),0) -> 33 | C21: =IFERROR(COUNTIFS('Cleaned Data '!R$2:R$301,Analysis!A21,'Cleaned Data '!K$2:K$301,"Yes"),0) -> 24 | D21: =C21/B21 -> 0.72727273 | E21: =IFERROR(AVERAGEIF('Cleaned Data '!R2:R301,Analysis!A21,'Cleaned Data '!L2:L301),0) -> 3.8181818 | F21: =IFERROR(AVERAGEIF('Cleaned Data '!R2:R301,Analysis!A21,'Cleaned Data '!I2:I301),0) -> 7.1306779 | G21: =IFERROR(COUNTIFS('Cleaned Data '!R2:R301,Analysis!A21,'Cleaned Data '!N2:N301,"Yes"),0) -> 5
A22: February | B22: =IFERROR(COUNTIF('Cleaned Data '!R3:R302,Analysis!A22),0) -> 32 | C22: =IFERROR(COUNTIFS('Cleaned Data '!R$2:R$301,Analysis!A22,'Cleaned Data '!K$2:K$301,"Yes"),0) -> 22 | D22: =C22/B22 -> 0.6875 | E22: =IFERROR(AVERAGEIF('Cleaned Data '!R3:R302,Analysis!A22,'Cleaned Data '!L3:L302),0) -> 3.71875 | F22: =IFERROR(AVERAGEIF('Cleaned Data '!R3:R302,Analysis!A22,'Cleaned Data '!I3:I302),0) -> 6.9876289 | G22: =IFERROR(COUNTIFS('Cleaned Data '!R3:R302,Analysis!A22,'Cleaned Data '!N3:N302,"Yes"),0) -> 5
A23: March | B23: =IFERROR(COUNTIF('Cleaned Data '!R4:R303,Analysis!A23),0) -> 20 | C23: =IFERROR(COUNTIFS('Cleaned Data '!R$2:R$301,Analysis!A23,'Cleaned Data '!K$2:K$301,"Yes"),0) -> 17 | D23: =C23/B23 -> 0.85 | E23: =IFERROR(AVERAGEIF('Cleaned Data '!R4:R303,Analysis!A23,'Cleaned Data '!L4:L303),0) -> 4.1 | F23: =IFERROR(AVERAGEIF('Cleaned Data '!R4:R303,Analysis!A23,'Cleaned Data '!I4:I303),0) -> 8.05 | G23: =IFERROR(COUNTIFS('Cleaned Data '!R4:R303,Analysis!A23,'Cleaned Data '!N4:N303,"Yes"),0) -> 2
A24: April | B24: =IFERROR(COUNTIF('Cleaned Data '!R5:R304,Analysis!A24),0) -> 23 | C24: =IFERROR(COUNTIFS('Cleaned Data '!R$2:R$301,Analysis!A24,'Cleaned Data '!K$2:K$301,"Yes"),0) -> 16 | D24: =C24/B24 -> 0.69565217 | E24: =IFERROR(AVERAGEIF('Cleaned Data '!R5:R304,Analysis!A24,'Cleaned Data '!L5:L304),0) -> 3.826087 | F24: =IFERROR(AVERAGEIF('Cleaned Data '!R5:R304,Analysis!A24,'Cleaned Data '!I5:I304),0) -> 7.7217391 | G24: =IFERROR(COUNTIFS('Cleaned Data '!R5:R304,Analysis!A24,'Cleaned Data '!N5:N304,"Yes"),0) -> 3
A25: May | B25: =IFERROR(COUNTIF('Cleaned Data '!R6:R305,Analysis!A25),0) -> 32 | C25: =IFERROR(COUNTIFS('Cleaned Data '!R$2:R$301,Analysis!A25,'Cleaned Data '!K$2:K$301,"Yes"),0) -> 24 | D25: =C25/B25 -> 0.75 | E25: =IFERROR(AVERAGEIF('Cleaned Data '!R6:R305,Analysis!A25,'Cleaned Data '!L6:L305),0) -> 3.75 | F25: =IFERROR(AVERAGEIF('Cleaned Data '!R6:R305,Analysis!A25,'Cleaned Data '!I6:I305),0) -> 7.7190077 | G25: =IFERROR(COUNTIFS('Cleaned Data '!R6:R305,Analysis!A25,'Cleaned Data '!N6:N305,"Yes"),0) -> 4
A26: June | B26: =IFERROR(COUNTIF('Cleaned Data '!R7:R306,Analysis!A26),0) -> 17 | C26: =IFERROR(COUNTIFS('Cleaned Data '!R$2:R$301,Analysis!A26,'Cleaned Data '!K$2:K$301,"Yes"),0) -> 14 | D26: =C26/B26 -> 0.82352941 | E26: =IFERROR(AVERAGEIF('Cleaned Data '!R7:R306,Analysis!A26,'Cleaned Data '!L7:L306),0) -> 3.8823529 | F26: =IFERROR(AVERAGEIF('Cleaned Data '!R7:R306,Analysis!A26,'Cleaned Data '!I7:I306),0) -> 7.4117647 | G26: =IFERROR(COUNTIFS('Cleaned Data '!R7:R306,Analysis!A26,'Cleaned Data '!N7:N306,"Yes"),0) -> 2
A27: July | B27: =IFERROR(COUNTIF('Cleaned Data '!R8:R307,Analysis!A27),0) -> 34 | C27: =IFERROR(COUNTIFS('Cleaned Data '!R$2:R$301,Analysis!A27,'Cleaned Data '!K$2:K$301,"Yes"),0) -> 29 | D27: =C27/B27 -> 0.85294118 | E27: =IFERROR(AVERAGEIF('Cleaned Data '!R8:R307,Analysis!A27,'Cleaned Data '!L8:L307),0) -> 4.1470588 | F27: =IFERROR(AVERAGEIF('Cleaned Data '!R8:R307,Analysis!A27,'Cleaned Data '!I8:I307),0) -> 7.7176471 | G27: =IFERROR(COUNTIFS('Cleaned Data '!R8:R307,Analysis!A27,'Cleaned Data '!N8:N307,"Yes"),0) -> 3
A28: August | B28: =IFERROR(COUNTIF('Cleaned Data '!R9:R308,Analysis!A28),0) -> 18 | C28: =IFERROR(COUNTIFS('Cleaned Data '!R$2:R$301,Analysis!A28,'Cleaned Data '!K$2:K$301,"Yes"),0) -> 14 | D28: =C28/B28 -> 0.77777778 | E28: =IFERROR(AVERAGEIF('Cleaned Data '!R9:R308,Analysis!A28,'Cleaned Data '!L9:L308),0) -> 4.2222222 | F28: =IFERROR(AVERAGEIF('Cleaned Data '!R9:R308,Analysis!A28,'Cleaned Data '!I9:I308),0) -> 7.9722222 | G28: =IFERROR(COUNTIFS('Cleaned Data '!R9:R308,Analysis!A28,'Cleaned Data '!N9:N308,"Yes"),0) -> 2
A29: September | B29: =IFERROR(COUNTIF('Cleaned Data '!R10:R309,Analysis!A29),0) -> 21 | C29: =IFERROR(COUNTIFS('Cleaned Data '!R$2:R$301,Analysis!A29,'Cleaned Data '!K$2:K$301,"Yes"),0) -> 13 | D29: =C29/B29 -> 0.61904762 | E29: =IFERROR(AVERAGEIF('Cleaned Data '!R10:R309,Analysis!A29,'Cleaned Data '!L10:L309),0) -> 3.7142857 | F29: =IFERROR(AVERAGEIF('Cleaned Data '!R10:R309,Analysis!A29,'Cleaned Data '!I10:I309),0) -> 8.1478154 | G29: =IFERROR(COUNTIFS('Cleaned Data '!R10:R309,Analysis!A29,'Cleaned Data '!N10:N309,"Yes"),0) -> 4
A30: October | B30: =IFERROR(COUNTIF('Cleaned Data '!R11:R310,Analysis!A30),0) -> 32 | C30: =IFERROR(COUNTIFS('Cleaned Data '!R$2:R$301,Analysis!A30,'Cleaned Data '!K$2:K$301,"Yes"),0) -> 24 | D30: =C30/B30 -> 0.75 | E30: =IFERROR(AVERAGEIF('Cleaned Data '!R11:R310,Analysis!A30,'Cleaned Data '!L11:L310),0) -> 3.5625 | F30: =IFERROR(AVERAGEIF('Cleaned Data '!R11:R310,Analysis!A30,'Cleaned Data '!I11:I310),0) -> 7.65 | G30: =IFERROR(COUNTIFS('Cleaned Data '!R11:R310,Analysis!A30,'Cleaned Data '!N11:N310,"Yes"),0) -> 1
A31: November | B31: =IFERROR(COUNTIF('Cleaned Data '!R12:R311,Analysis!A31),0) -> 16 | C31: =IFERROR(COUNTIFS('Cleaned Data '!R$2:R$301,Analysis!A31,'Cleaned Data '!K$2:K$301,"Yes"),0) -> 13 | D31: =C31/B31 -> 0.8125 | E31: =IFERROR(AVERAGEIF('Cleaned Data '!R12:R311,Analysis!A31,'Cleaned Data '!L12:L311),0) -> 4 | F31: =IFERROR(AVERAGEIF('Cleaned Data '!R12:R311,Analysis!A31,'Cleaned Data '!I12:I311),0) -> 7.7755155 | G31: =IFERROR(COUNTIFS('Cleaned Data '!R12:R311,Analysis!A31,'Cleaned Data '!N12:N311,"Yes"),0) -> 0
A32: December | B32: =IFERROR(COUNTIF('Cleaned Data '!R13:R312,Analysis!A32),0) -> 20 | C32: =IFERROR(COUNTIFS('Cleaned Data '!R$2:R$301,Analysis!A32,'Cleaned Data '!K$2:K$301,"Yes"),0) -> 14 | D32: =C32/B32 -> 0.7 | E32: =IFERROR(AVERAGEIF('Cleaned Data '!R13:R312,Analysis!A32,'Cleaned Data '!L13:L312),0) -> 4.2 | F32: =IFERROR(AVERAGEIF('Cleaned Data '!R13:R312,Analysis!A32,'Cleaned Data '!I13:I312),0) -> 7.62 | G32: =IFERROR(COUNTIFS('Cleaned Data '!R13:R312,Analysis!A32,'Cleaned Data '!N13:N312,"Yes"),0) -> 3
A34: 📊 D. Agent Performance Scorecard
A35: Agent ID | B35: Agent Name | C35: Total Cases | D35: FCR Rate | E35: Avg CSAT | F35: Avg Handle Time | G35: Escalation Rate | H35: Performance Tag
A36: AG001 | B36: Alice Uwimana | C36: =IFERROR(COUNTIF('Cleaned Data '!D$2:D$301,Analysis!B36),0) -> 26 | D36: =IFERROR(COUNTIFS('Cleaned Data '!D$2:D$301,Analysis!B36,'Cleaned Data '!K$2:K$301,"Yes"),0)/C36 -> 0.61538462 | E36: =IFERROR(AVERAGEIF('Cleaned Data '!D$2:D$301,Analysis!B36,'Cleaned Data '!L$2:L$301),0) -> 3.6538462 | F36: =IFERROR(AVERAGEIF('Cleaned Data '!D$2:D$301,Analysis!B36,'Cleaned Data '!I$2:I$301),0) -> 8.1770817 | G36: =IFERROR(COUNTIFS('Cleaned Data '!D$2:D$301,Analysis!B36,'Cleaned Data '!N$2:N$301,"Yes"),0)/C36 -> 0.26923077
A37: AG002 | B37: Bob Nshimiyimana | C37: =IFERROR(COUNTIF('Cleaned Data '!D$2:D$301,Analysis!B37),0) -> 37 | D37: =IFERROR(COUNTIFS('Cleaned Data '!D$2:D$301,Analysis!B37,'Cleaned Data '!K$2:K$301,"Yes"),0)/C37 -> 0.67567568 | E37: =IFERROR(AVERAGEIF('Cleaned Data '!D$2:D$301,Analysis!B37,'Cleaned Data '!L$2:L$301),0) -> 3.5945946 | F37: =IFERROR(AVERAGEIF('Cleaned Data '!D$2:D$301,Analysis!B37,'Cleaned Data '!I$2:I$301),0) -> 7.2811925 | G37: =IFERROR(COUNTIFS('Cleaned Data '!D$2:D$301,Analysis!B37,'Cleaned Data '!N$2:N$301,"Yes"),0)/C37 -> 0.13513514
A38: AG003 | B38: Claire Mukamana | C38: =IFERROR(COUNTIF('Cleaned Data '!D$2:D$301,Analysis!B38),0) -> 33 | D38: =IFERROR(COUNTIFS('Cleaned Data '!D$2:D$301,Analysis!B38,'Cleaned Data '!K$2:K$301,"Yes"),0)/C38 -> 0.72727273 | E38: =IFERROR(AVERAGEIF('Cleaned Data '!D$2:D$301,Analysis!B38,'Cleaned Data '!L$2:L$301),0) -> 4.030303 | F38: =IFERROR(AVERAGEIF('Cleaned Data '!D$2:D$301,Analysis!B38,'Cleaned Data '!I$2:I$301),0) -> 7.7060606 | G38: =IFERROR(COUNTIFS('Cleaned Data '!D$2:D$301,Analysis!B38,'Cleaned Data '!N$2:N$301,"Yes"),0)/C38 -> 0.060606061
A39: AG004 | B39: David Habimana | C39: =IFERROR(COUNTIF('Cleaned Data '!D$2:D$301,Analysis!B39),0) -> 33 | D39: =IFERROR(COUNTIFS('Cleaned Data '!D$2:D$301,Analysis!B39,'Cleaned Data '!K$2:K$301,"Yes"),0)/C39 -> 0.75757576 | E39: =IFERROR(AVERAGEIF('Cleaned Data '!D$2:D$301,Analysis!B39,'Cleaned Data '!L$2:L$301),0) -> 3.8484848 | F39: =IFERROR(AVERAGEIF('Cleaned Data '!D$2:D$301,Analysis!B39,'Cleaned Data '!I$2:I$301),0) -> 7.7727273 | G39: =IFERROR(COUNTIFS('Cleaned Data '!D$2:D$301,Analysis!B39,'Cleaned Data '!N$2:N$301,"Yes"),0)/C39 -> 0.12121212
A40: AG005 | B40: Eve Ingabire | C40: =IFERROR(COUNTIF('Cleaned Data '!D$2:D$301,Analysis!B40),0) -> 28 | D40: =IFERROR(COUNTIFS('Cleaned Data '!D$2:D$301,Analysis!B40,'Cleaned Data '!K$2:K$301,"Yes"),0)/C40 -> 0.82142857 | E40: =IFERROR(AVERAGEIF('Cleaned Data '!D$2:D$301,Analysis!B40,'Cleaned Data '!L$2:L$301),0) -> 4.0357143 | F40: =IFERROR(AVERAGEIF('Cleaned Data '!D$2:D$301,Analysis!B40,'Cleaned Data '!I$2:I$301),0) -> 7.6965758 | G40: =IFERROR(COUNTIFS('Cleaned Data '!D$2:D$301,Analysis!B40,'Cleaned Data '!N$2:N$301,"Yes"),0)/C40 -> 0.10714286
A41: AG006 | B41: Frank Nzeyimana | C41: =IFERROR(COUNTIF('Cleaned Data '!D$2:D$301,Analysis!B41),0) -> 28 | D41: =IFERROR(COUNTIFS('Cleaned Data '!D$2:D$301,Analysis!B41,'Cleaned Data '!K$2:K$301,"Yes"),0)/C41 -> 0.82142857 | E41: =IFERROR(AVERAGEIF('Cleaned Data '!D$2:D$301,Analysis!B41,'Cleaned Data '!L$2:L$301),0) -> 3.9285714 | F41: =IFERROR(AVERAGEIF('Cleaned Data '!D$2:D$301,Analysis!B41,'Cleaned Data '!I$2:I$301),0) -> 6.8785714 | G41: =IFERROR(COUNTIFS('Cleaned Data '!D$2:D$301,Analysis!B41,'Cleaned Data '!N$2:N$301,"Yes"),0)/C41 -> 0.10714286
A42: AG007 | B42: Grace Uwase | C42: =IFERROR(COUNTIF('Cleaned Data '!D$2:D$301,Analysis!B42),0) -> 28 | D42: =IFERROR(COUNTIFS('Cleaned Data '!D$2:D$301,Analysis!B42,'Cleaned Data '!K$2:K$301,"Yes"),0)/C42 -> 0.71428571 | E42: =IFERROR(AVERAGEIF('Cleaned Data '!D$2:D$301,Analysis!B42,'Cleaned Data '!L$2:L$301),0) -> 3.9642857 | F42: =IFERROR(AVERAGEIF('Cleaned Data '!D$2:D$301,Analysis!B42,'Cleaned Data '!I$2:I$301),0) -> 7.0465758 | G42: =IFERROR(COUNTIFS('Cleaned Data '!D$2:D$301,Analysis!B42,'Cleaned Data '!N$2:N$301,"Yes"),0)/C42 -> 0.071428571
A43: AG008 | B43: Henry Bizimana | C43: =IFERROR(COUNTIF('Cleaned Data '!D$2:D$301,Analysis!B43),0) -> 28 | D43: =IFERROR(COUNTIFS('Cleaned Data '!D$2:D$301,Analysis!B43,'Cleaned Data '!K$2:K$301,"Yes"),0)/C43 -> 0.85714286 | E43: =IFERROR(AVERAGEIF('Cleaned Data '!D$2:D$301,Analysis!B43,'Cleaned Data '!L$2:L$301),0) -> 4.2857143 | F43: =IFERROR(AVERAGEIF('Cleaned Data '!D$2:D$301,Analysis!B43,'Cleaned Data '!I$2:I$301),0) -> 8.1075847 | G43: =IFERROR(COUNTIFS('Cleaned Data '!D$2:D$301,Analysis!B43,'Cleaned Data '!N$2:N$301,"Yes"),0)/C43 -> 0.071428571
A44: AG009 | B44: Irene Mutesi | C44: =IFERROR(COUNTIF('Cleaned Data '!D$2:D$301,Analysis!B44),0) -> 28 | D44: =IFERROR(COUNTIFS('Cleaned Data '!D$2:D$301,Analysis!B44,'Cleaned Data '!K$2:K$301,"Yes"),0)/C44 -> 0.78571429 | E44: =IFERROR(AVERAGEIF('Cleaned Data '!D$2:D$301,Analysis!B44,'Cleaned Data '!L$2:L$301),0) -> 3.8214286 | F44: =IFERROR(AVERAGEIF('Cleaned Data '!D$2:D$301,Analysis!B44,'Cleaned Data '!I$2:I$301),0) -> 7.2107143 | G44: =IFERROR(COUNTIFS('Cleaned Data '!D$2:D$301,Analysis!B44,'Cleaned Data '!N$2:N$301,"Yes"),0)/C44 -> 0.071428571
...

Sheet Sheet1
A1: Count of Case_ID | B1: Column Labels | I1: Date | J1: (All)
